<?xml version='1.0'?>

<robot name="my_robot" xmlns:xacro="http://www.ros.org/wiki/xacro">

  <link name="robot_footprint"></link>

  <joint name="robot_footprint_joint" type="fixed">
    <origin xyz="0 0 0" rpy="0 0 0" />
    <parent link="robot_footprint"/>
    <child link="chassis" />
  </joint>

  <link name='chassis'>
    <pose>0 0 0.1 0 0 0</pose>

    <inertial>
      <mass value="15.0"/>
      <origin xyz="0.0 0 0" rpy=" 0 0 0"/>
      <inertia
          ixx="0.1" ixy="0" ixz="0"
          iyy="0.1" iyz="0"
          izz="0.1"
      />
    </inertial>

    <collision name='collision'>
      <origin xyz="0 0 0" rpy=" 0 0 0"/> 
      <geometry>
        <box size=".6 .3 .1"/>
      </geometry>
    </collision>

    <visual name='chassis_visual'>
      <origin xyz="0 0 0" rpy=" 0 0 0"/>
      <geometry>
        <box size=".6 .3 .1"/>
      </geometry>
    </visual>


    <collision name='back_caster_collision'>
      <origin xyz="-0.15 0 -0.05" rpy=" 0 0 0"/>
      <geometry>
        <sphere radius="0.0499"/>
      </geometry>
    </collision>

    <visual name='back_caster_visual'>
      <origin xyz="-0.15 0 -0.05" rpy=" 0 0 0"/>
      <geometry>
        <sphere radius="0.05"/>
      </geometry>
    </visual>

    <collision name='front_caster_collision'>
      <origin xyz="0.15 0 -0.05" rpy=" 0 0 0"/>
      <geometry>
        <sphere radius="0.0499"/>
      </geometry>
    </collision>

    <visual name='front_caster_visual'>
      <origin xyz="0.15 0 -0.05" rpy=" 0 0 0"/>
      <geometry>
        <sphere radius="0.05"/>
      </geometry>
    </visual>

  </link>

  <link name="front_left_wheel">
    <pose>0 0 0 0 0 0</pose>

    <inertial>
      <mass value="5.0"/>
      <origin xyz="0.0 0 0" rpy=" 0 1.5707 1.5707"/>
      <inertia
          ixx="0.1" ixy="0" ixz="0"
          iyy="0.1" iyz="0"
          izz="0.1"
      />
    </inertial>

    <visual>
      <origin xyz="0 0 0" rpy=" 0 1.5707 1.5707"/> 
      <geometry>
        <cylinder radius="0.1" length="0.05"/>
      </geometry>
    </visual>

    <collision name="collision_front_left_wheel">
      <origin xyz="0 0 0" rpy=" 0 1.5707 1.5707"/> 
      <geometry>
        <cylinder radius="0.1" length="0.05"/>
      </geometry>
    </collision>
  </link>


  <link name="front_right_wheel">
    <pose>0 0 0 0 0 0</pose>

    <inertial>
      <mass value="5.0"/>
      <origin xyz="0.0 0 0" rpy=" 0 1.5707 1.5707"/>
      <inertia
          ixx="0.1" ixy="0" ixz="0"
          iyy="0.1" iyz="0"
          izz="0.1"
      />
    </inertial>

    <visual>
      <origin xyz="0 0 0" rpy=" 0 1.5707 1.5707"/> 
      <geometry>
        <cylinder radius="0.1" length="0.05"/>
      </geometry>
    </visual>

    <collision>
      <origin xyz="0 0 0" rpy=" 0 1.5707 1.5707"/> 
      <geometry>
        <cylinder radius="0.1" length="0.05"/>
      </geometry>
    </collision>
  </link>

  <link name="back_left_wheel">
    <pose>0 0 0 0 0 0</pose>

    <inertial>
      <mass value="5.0"/>
      <origin xyz="0.0 0 0" rpy=" 0 1.5707 1.5707"/>
      <inertia
          ixx="0.1" ixy="0" ixz="0"
          iyy="0.1" iyz="0"
          izz="0.1"
      />
    </inertial>

    <visual>
      <origin xyz="0 0 0" rpy=" 0 1.5707 1.5707"/> 
      <geometry>
        <cylinder radius="0.1" length="0.05"/>
      </geometry>
    </visual>

    <collision>
      <origin xyz="0 0 0" rpy=" 0 1.5707 1.5707"/> 
      <geometry>
        <cylinder radius="0.1" length="0.05"/>
      </geometry>
    </collision>
  </link>

  <link name="back_right_wheel">
    <pose>0 0 0 0 0 0</pose>

    <inertial>
      <mass value="5.0"/>
      <origin xyz="0.0 0 0" rpy=" 0 1.5707 1.5707"/>
      <inertia
          ixx="0.1" ixy="0" ixz="0"
          iyy="0.1" iyz="0"
          izz="0.1"
      />
    </inertial>

    <visual>
      <origin xyz="0 0 0" rpy=" 0 1.5707 1.5707"/> 
      <geometry>
        <cylinder radius="0.1" length="0.05"/>
      </geometry>
    </visual>

    <collision>
      <origin xyz="0 0 0" rpy=" 0 1.5707 1.5707"/> 
      <geometry>
        <cylinder radius="0.1" length="0.05"/>
      </geometry>
    </collision>
  </link>

  <joint name="JOINT_front_left_wheel" type="continuous">
    <parent link="robot_footprint"/>
    <child link="front_left_wheel"/>
    <origin xyz=".2 0.175 0" rpy="0 0 0"/>
    <axis xyz="0 1 0" rpy="0 0 0"/>
    <limit effort="10000" velocity="1000"/>
    <dynamics damping="1.0" friction="1.0"/>
  </joint>

  <joint name="JOINT_front_right_wheel" type="continuous">
    <parent link="robot_footprint"/>
    <child link="front_right_wheel"/>
    <origin xyz=".2 -0.175 0" rpy="0 0 0"/>
    <axis xyz="0 1 0" rpy="0 0 0"/>
    <limit effort="10000" velocity="1000"/>
    <dynamics damping="1.0" friction="1.0"/>
  </joint>


  <joint name="JOINT_back_left_wheel" type="continuous">
    <parent link="robot_footprint"/>
    <child link="back_left_wheel"/>
    <origin xyz="-.2 0.175 0" rpy="0 0 0"/>
    <axis xyz="0 1 0" rpy="0 0 0"/>
    <limit effort="10000" velocity="1000"/>
    <dynamics damping="1.0" friction="1.0"/>
  </joint>

  <joint name="JOINT_back_right_wheel" type="continuous">
    <parent link="robot_footprint"/>
    <child link="back_right_wheel"/>
    <origin xyz="-.2 -0.175 0" rpy="0 0 0"/>
    <axis xyz="0 1 0" rpy="0 0 0"/>
    <limit effort="10000" velocity="1000"/>
    <dynamics damping="1.0" friction="1.0"/>
  </joint>


</robot>
